<?xml version="1.0"?>

<robot name="r2d2">

    <link name="robot_base">
        <visual>
            <origin xyz="0 0 0.25" rpy="0 0 0"/>
            <geometry>
                <box size="0.4 0.4 0.5" />
            </geometry>
        </visual>
        <collision>
             <geometry>
                <box size="0.4 0.4 0.5" />
            </geometry>
        </collision>
    </link>

    <!-- left wheels -->
    <link name="left_wheel1">
        <visual>
            <geometry>
                <cylinder radius="0.07" length="0.05"/>
            </geometry>
        </visual>
        <collision>
             <geometry>
                <cylinder radius="0.07" length="0.05"/>
            </geometry>
        </collision>
    </link>

    <joint name="left_wheel1_joint" type="continuous">
        <parent link="robot_base"/>
        <child link="left_wheel1"/>
        <origin xyz="-0.1 0.22 0" rpy="-1.5707 0 0"/>
        <axis xyz="0 0 1"/>
    </joint>

    <link name="left_wheel2">
        <visual>
            <geometry>
                <cylinder radius="0.07" length="0.05"/>
            </geometry>
        </visual>
        <collision>
             <geometry>
                <cylinder radius="0.07" length="0.05"/>
            </geometry>
        </collision>
    </link>

    <joint name="left_wheel2_joint" type="continuous">
        <parent link="robot_base"/>
        <child link="left_wheel2"/>
        <origin xyz="0.1 0.22 0" rpy="-1.5707 0 0"/>
        <axis xyz="0 1 0"/>
    </joint>


    <!-- right wheels -->


    <link name="right_wheel1">
        <visual>
            <geometry>
                <cylinder radius="0.07" length="0.05"/>
            </geometry>
        </visual>
        <collision>
             <geometry>
                <cylinder radius="0.07" length="0.05"/>
            </geometry>
        </collision>
    </link>

    <joint name="right_wheel1_joint" type="continuous">
        <parent link="robot_base"/>
        <child link="right_wheel1"/>
        <origin xyz="-0.1 -0.22 0" rpy="-1.5707 0 0"/>
        <axis xyz="0 1 0"/>
    </joint>

    <link name="right_wheel2">
        <visual>
            <geometry>
                <cylinder radius="0.07" length="0.05"/>
            </geometry>
        </visual>
        <collision>
             <geometry>
                <cylinder radius="0.07" length="0.05"/>
            </geometry>
        </collision>
    </link>

    <joint name="right_wheel2_joint" type="continuous">
        <parent link="robot_base"/>
        <child link="right_wheel2"/>
        <origin xyz="0.1 -0.22 0" rpy="-1.5707 0 0"/>
        <axis xyz="0 1 0"/>
    </joint>

</robot>